<?xml version="1.0"?>
<robot name="mini_unix" xmlns:xacro="http://ros.org/wiki/xacro">

  <xacro:include filename="$(find sdv_test)/urdf/common_properties.xacro"/>
  <xacro:include filename="$(find sdv_test)/urdf/fresh.gazebo.xacro"/>

  <xacro:property name="scale" value="0.4"/>

  <joint name="base_to_footprint" type="fixed">
    <parent link="base_footprint"/>
    <child link="base_link"/>
    <origin xyz="0 0 0" rpy="0 0 0"/>
  </joint>

  <link name="base_footprint"/>

  <link name="base_link">
    <visual>
      <origin xyz="0 0 0" rpy="0 0 0"/>
      <geometry>
        <mesh filename="package://sdv_test/urdf/base3.stl" scale="${scale * 1} ${scale * 1} ${scale * 1}"/>
      </geometry>
      <material name="base"/>
    </visual>

    <collision>
      <origin xyz="0 0 0" rpy="0 0 3.14"/>
      <geometry>
        <box size="${1.12 * scale} ${scale * 0.857} ${scale * 0.28}"/>
      </geometry>
    </collision>

    <inertial>
      <origin xyz="0 0 0" rpy="0 0 0"/>
      <mass value="${scale * 20}"/>
      <inertia ixx="${scale * 0.067737}" ixy="0" ixz="0"
               iyy="${scale * 0.108202}" iyz="0"
               izz="${scale * 0.162873}"/>
    </inertial>
  </link>

  <joint name="bottom_to_base" type="fixed">
    <parent link="base_link"/>
    <child link="bottom_base"/>
    <origin xyz="0 0 ${scale * -0.14}"/>
  </joint>

  <link name="bottom_base">
    <visual>
      <origin xyz="0 0 0" rpy="0 0 3.1415"/>
      <geometry>
        <mesh filename="package://sdv_test/urdf/basebottom.stl" scale="${scale * 1} ${scale * 1} ${scale * 1}"/>
      </geometry>
      <material name="black"/>
    </visual>

    <collision>
      <origin xyz="0 0 0" rpy="0 0 0"/>
      <geometry>
        <box size="${scale * 1.105} ${scale * 0.857} ${scale * 0.01}"/>
      </geometry>
    </collision>

    <inertial>
      <origin xyz="0 0 0" rpy="0 0 0"/>
    <mass value="${scale * 6}"/>
    <inertia ixx="${scale * 0.067737}" ixy="0" ixz="0" 
             iyy="${scale * 0.108202}" iyz="0.0" 
             izz="${scale * 0.162873}"/>
    </inertial>
  </link>

  <joint name="left_back_joint" type="continuous">
    <parent link="base_footprint"/>
    <child link="left_back_wheel"/>
    <origin rpy="0 0 0" xyz="${scale * -0.330} ${scale * 0.310} ${scale * -0.07}"/>
    <axis xyz="0 1 0"/>
  </joint>

  <link name="left_back_wheel">
    <visual>
      <origin rpy="1.57075 0 0" xyz="0 0 0"/>
      <geometry>
        <cylinder length="${scale * 0.07}" radius="${scale * 0.12}"/>
      </geometry>
      <material name="red"/>
    </visual>

    <collision>
      <origin xyz="0 0 0" rpy="1.57075 0 0"/>
      <geometry>
        <cylinder length="${scale * 0.07}" radius="${scale * 0.12}"/>
      </geometry>
    </collision>

    <inertial>
      <origin rpy="1.57075 0 0"/>
      <mass value="${scale * 1}"/>
      <inertia 
        ixx="${scale * 0.0040083}" ixy="0" ixz="0" 
        iyy="${scale * 0.0040083}" iyz="0.0" 
        izz="${scale * 0.0072}"/>
    </inertial>
  </link>

  <joint name="right_back_joint" type="continuous">
    <parent link="base_footprint"/>
    <child link="right_back_wheel"/>
    <origin rpy="0 0 0" xyz="${scale * -0.330} ${scale * -0.310} ${scale * -0.07}"/> 
    <axis xyz="0 1 0"/>
  </joint>  

  <link name="right_back_wheel">
    <visual>
      <origin xyz="0 0 0" rpy="1.57075 0 0"/>
      <geometry>
        <cylinder length="${scale * 0.07}" radius="${scale * 0.12}"/>
      </geometry>
      <material name="red"/>
    </visual>
    
    <collision>
      <origin xyz="0 0 0" rpy="1.57075 0 0"/>
      <geometry>
        <cylinder length="${scale * 0.07}" radius="${scale * 0.12}"/>
      </geometry>
    </collision>

    <inertial>
      <origin rpy="1.57075 0 0"/>
      <mass value="${scale * 1}"/>
      <inertia 
        ixx="${scale * 0.0040083}" ixy="0" ixz="0" 
        iyy="${scale * 0.0040083}" iyz="0.0" 
        izz="${scale * 0.0072}"/>
    </inertial>
  </link>

  <joint name="left_castor_joint" type="fixed">
    <parent link="base_link"/>
    <child link="left_castor_wheel"/>
    <origin rpy="0 0 0" xyz="${scale * 0.370} ${scale * -0.310} ${scale * -0.14}"/>
  </joint>

  <link name="left_castor_wheel">
    <visual>
      <origin xyz="0 0 0" rpy="0 0 0"/>
      <geometry>
        <sphere radius="${scale * 0.05}"/>
      </geometry>
      <material name="red"/>
    </visual>

    <collision>
      <origin xyz="0 0 0" rpy="0 0 0"/>
      <geometry>
        <sphere radius="${scale * 0.05}"/>
      </geometry>
    </collision>

    <inertial>
      <origin xyz="0 0 0" />
      <mass value="${scale * 0.8}"/>
      <inertia 
        ixx="${scale * 0.0001}" ixy="0" ixz="0" 
        iyy="${scale * 0.0001}" iyz="0.0" 
        izz="${scale * 0.0001}"/>
    </inertial>
  </link>

  <joint name="right_castor_joint" type="fixed">
    <parent link="base_link"/>
    <child link="right_castor_wheel"/>
    <origin rpy="0 0 0" xyz="${scale * 0.370} ${scale * 0.310} ${scale * -0.14}"/>
  </joint> 

  <link name="right_castor_wheel">
    <visual>
      <origin rpy="0 0 0" xyz="0 0 0"/>
      <geometry>
        <sphere radius="${scale * 0.05}"/>
      </geometry>
      <material name="red"/>
    </visual>

    <collision>
      <origin xyz="0 0 0" rpy="0 0 0"/>
      <geometry>
        <sphere radius="${scale * 0.05}"/>
      </geometry>
    </collision>

    <inertial>
      <mass value="${scale * 0.8}"/>
      <origin rpy="0 0 0" xyz="0 0 0"/>
      <inertia 
        ixx="${scale * 0.0001}" ixy="0" ixz="0" 
        iyy="${scale * 0.0001}" iyz="0.0" 
        izz="${scale * 0.0001}"/>
    </inertial>
  </link>

  <!-- <joint name="laser_joint" type="fixed">
    <parent link="base_link"/>
    <child link="laser_link"/>
    <origin xyz="0 0 ${scale * 0.18}" rpy="0 0 0"/>
  </joint>

  <link name="laser_link">
    <visual>
      <origin xyz="0 0 0" rpy="0 0 0" />
      <geometry>
        <cylinder length="${scale * 0.08}" radius="${scale * 0.12}"/>
      </geometry>
      <material name="blue"/>
    </visual>

    <collision>
      <origin xyz="0 0 0" rpy="0 0 0"/>
      <geometry>
        <cylinder length="${scale * 0.08}" radius="${scale * 0.05}"/>
      </geometry>
    </collision>

    <inertial>
      <origin xyz="0 0 0" rpy="0 0 0"/>
      <mass value="${scale * 0.001}"/>
      <inertia ixx="0.0000040083" ixy="0" ixz="0"
               iyy="0.0000040083" iyz="0"
               izz="0.0000072"/>
    </inertial>
  </link> -->
  
  <joint name="laser_rear_joint" type="fixed">
    <parent link="base_footprint"/>
    <child link="laser_rear_link"/>
    <origin xyz="${scale * -0.4025} ${scale * -0.2785} ${scale * 0.17}" rpy="0 0 3.14159265"/>
    <axis xyz="0 0 1"/>
  </joint>

  <link name="laser_rear_link">
    <visual>
      <origin xyz="0 0 0" rpy="0 0 0" />
      <geometry>
        <cylinder length="${scale * 0.06}" radius="${scale * 0.06}"/>
      </geometry>
      <material name="blue"/>
    </visual>
  </link>

  <joint name="laser_front_joint" type="fixed">
    <parent link="base_footprint"/>
    <child link="laser_front_link"/>
    <origin xyz="${scale * 0.4025} ${scale * 0.2785} ${scale * 0.17}" rpy="0 0 0"/>
    <axis xyz="0 0 1"/>
  </joint>

  <link name="laser_front_link">
    <visual>
      <origin xyz="0 0 0" rpy="0 0 0" />
      <geometry>
        <cylinder length="${scale * 0.06}" radius="${scale * 0.06}"/>
      </geometry>
      <material name="blue"/>
    </visual>
  </link>
  
  <gazebo>
    <plugin name="gazebo_ros_control" filename="libgazebo_ros_control.so">
      <robotSimType>gazebo_ros_control/DefaultRobotHWSim</robotSimType>
    </plugin>
  </gazebo>
</robot>